Workbook

Sheet README
A1: H₂ Transmission Pipeline Cost Model — Transition Accelerator Extraction Framework
A3: Purpose | B3: Intended Use
A4: This workbook reconstructs and documents the engineering and cost models for new-build gaseous hydrogen transmission pipelines and associated compression systems. It reproduces source calculations from the Transition Accelerator pipeline and compression technical briefs, uses the Ziqi Wei thesis as an implementation and validation reference, converts source costs into a consistent currency and unit basis, and prepares the resulting capital, fixed operating, variable operating, and electricity requirements for mapping into CANOE/TEMOA | B4: The workbook is designed to support transparent extraction, validation, sensitivity analysis, and implementation of hydrogen transmission cost parameters. It is not intended to calculate a single levelized cost of hydrogen for direct use in CANOE/TEMOA. Instead, it separates investment, fixed operating, variable operating, and energy requirements so that the optimization model can apply its own capacity, activity, lifetime, discounting, and temporal structure. | D4: TEMOA Cost Structure
A5: Sheet | B5: Role | D5: Parameter | E5: Economic Meaning | F5: Units | G5: Note
A6: Source_Index | B6: Records source information used for parameters, including source document, section, table or equation, original unit, extraction status, and interpretation notes.
A7: Assumptions and Parameters, Pipe | B7: Stores source-derived and explicitly assumed physical, hydraulic, economic, and conversion inputs used by the pipeline model.
A8: Transition Accelerator Pipe | B8: Reconstructs pipeline capacity, capital cost, fixed operating cost, and related outputs across the selected pipeline design cases.
A9: Assumptions and Parameters, Comp | B9: Stores source-derived and explicitly assumed thermodynamic, equipment, economic, and conversion inputs used by the compressor model.
A10: Transition Accelerator Comp | B10: Reconstructs compressor staging, power, capital cost, fixed operating cost, and electricity requirements for each pipeline capacity case.
A11: Normalized Transmission Costs | B11: Combines pipeline and compressor outputs into a consistent capacity-indexed transmission dataset using common currency, distance, capacity, and time conventions.
A12: Temoa cost structure | B12: Maps normalized transmission outputs into CANOE/TEMOA parameter definitions and units, including piecewise capacity-cost segments, fixed costs, variable costs, electricity inputs, and lifetime.
A14: System Boundary
A15: Included | B15: Excluded
A16: new-build gaseous hydrogen transmission pipelines | B16: Hydrogen production
A17: Pipeline material, labour, miscellaneous, installation, right-of-way costs included by the transition accelerator source | B17: Hydrogen storage
A18: Pipeline capital, fixed and variable costs | B18: End-use distribution networks
A19: Inlet compression | B19: Fueling station compression
A20: Compressor capital, fixed and variable costs | B20: Terminal end-fuel infrastructure
A21: En-route recompression normalized per km | B21: Seasonal operating dyanmics
A22: Compressor electricity requirements | B22: Geographic consutrction cost multipliers
A23: Capacity-dependent economies of scale | B23: Natural-gas pipeline repurposing
A24: Currency conversion and cost normalization | B24: Financing and discount (performed by TEMOA across all cost models)
A25: Mapping to TEMOA cost and efficicency parameters | B25: Taxes, subsidies, carbon pricing, or policy incentives

Sheet Source_Index
A1: Source Extraction Log: Transmission Pipeline Component
A2: Source_ID | B2: Source_Type | C2: Title | D2: Year/Version | E2: Section | F2: Source Page | G2: Table / Equation / Figure | H2: Default Value | I2: Unit | J2: Workbook symbol | K2: Workbook Section | L2: Notes | M2: Source URL
A3: TA-PIPE-001 | B3: Primary technical source | C3: The Techno-Economics of Hydrogen Pipelines | D3: 2021 / Version 2 | E3: 5.3 Pipeline Levelized Cost | F3: 20 | G3: Table 5.2 | H3: 50 | I3: years | J3: pipeline_lifetime | K3: Assumptions and Parameters Pipe – Pipeline lifetime | L3: Physical pipeline lifetime reported by the source. Use as the technology lifetime; do not embed a capital recovery factor in CostInvest. | M3: https://transitionaccelerator.ca/wp-content/uploads/2023/06/The-Techno-Economics-of-Hydrogen-Pipelines-v2.pdf
A4: TA-PIPE-002 | B4: Primary technical source | C4: The Techno-Economics of Hydrogen Pipelines | D4: 2021 / Version 2 | E4: 5.1 Pipeline Capital Costs | F4: 17 | G4: Table 5.1 notes | H4: 1.1 | I4: multiplier | J4: hydrogen_pipeline_cost_multiplier | K4: Assumptions and Parameters Pipe – Hydrogen pipeline cost multiplier | L4: Source applies a 1.1 hydrogen adjustment to the material, construction-labour, and miscellaneous transmission-pipeline correlations, but not to right-of-way. Retain for source reproduction and sensitivity analysis. | M4: https://transitionaccelerator.ca/wp-content/uploads/2023/06/The-Techno-Economics-of-Hydrogen-Pipelines-v2.pdf
A5: TA-PIPE-003 | B5: Primary technical source | C5: The Techno-Economics of Hydrogen Pipelines | D5: 2021 / Version 2 | E5: 5.1 Pipeline Capital Costs | F5: 18 | G5: Equation 14 | H5: 0.4 | I5: fraction of TIC | J5: indirect_capex_fraction | K5: Assumptions and Parameters Pipe – Indirect CAPEX cost assumption multiplier | L5: Indirect capital costs are calculated as 40% of total installed cost. The listed components total 28%, so the source also contains an unexplained residual of 12 percentage points. | M5: https://transitionaccelerator.ca/wp-content/uploads/2023/06/The-Techno-Economics-of-Hydrogen-Pipelines-v2.pdf
A6: TA-PIPE-004 | B6: Primary technical source | C6: The Techno-Economics of Hydrogen Pipelines | D6: 2021 / Version 2 | E6: 5.1 Pipeline Capital Costs | F6: 18 | G6: Indirect-capital-cost breakdown | H6: 0.05 | I6: fraction of TIC | J6: site_preparation_fraction | K6: Assumptions and Parameters Pipe – Site preparation | L6: Includes land purchase, grading, excavation, utilities, internal roads, walkways, and parking areas. Component of the 40% total indirect-cost assumption. | M6: https://transitionaccelerator.ca/wp-content/uploads/2023/06/The-Techno-Economics-of-Hydrogen-Pipelines-v2.pdf
A7: TA-PIPE-005 | B7: Primary technical source | C7: The Techno-Economics of Hydrogen Pipelines | D7: 2021 / Version 2 | E7: 5.1 Pipeline Capital Costs | F7: 18 | G7: Indirect-capital-cost breakdown | H7: 0.1 | I7: fraction of TIC | J7: engineering_design_fraction | K7: Assumptions and Parameters Pipe – Engineering and Design | L7: Includes engineering, drafting, project management, salaries, and associated overhead. Component of the 40% total indirect-cost assumption. | M7: https://transitionaccelerator.ca/wp-content/uploads/2023/06/The-Techno-Economics-of-Hydrogen-Pipelines-v2.pdf
A8: TA-PIPE-006 | B8: Primary technical source | C8: The Techno-Economics of Hydrogen Pipelines | D8: 2021 / Version 2 | E8: 5.1 Pipeline Capital Costs | F8: 18 | G8: Indirect-capital-cost breakdown | H8: 0.1 | I8: fraction of TIC | J8: project_contingency_fraction | K8: Assumptions and Parameters Pipe – Project Contingency | L8: Covers unforeseen circumstances, project risks, design changes, delays, and unexpected price increases. Component of the 40% total indirect-cost assumption. | M8: https://transitionaccelerator.ca/wp-content/uploads/2023/06/The-Techno-Economics-of-Hydrogen-Pipelines-v2.pdf
A9: TA-PIPE-007 | B9: Primary technical source | C9: The Techno-Economics of Hydrogen Pipelines | D9: 2021 / Version 2 | E9: 5.1 Pipeline Capital Costs | F9: 18 | G9: Indirect-capital-cost breakdown | H9: 0.03 | I9: fraction of TIC | J9: capital_permitting_fraction | K9: Assumptions and Parameters Pipe – Permitting | L9: One-time capital permitting allowance. Distinct from recurring annual licensing and permitting OPEX. Component of the 40% total indirect-cost assumption. | M9: https://transitionaccelerator.ca/wp-content/uploads/2023/06/The-Techno-Economics-of-Hydrogen-Pipelines-v2.pdf
A10: TA-PIPE-008 | B10: Primary technical source | C10: The Techno-Economics of Hydrogen Pipelines | D10: 2021 / Version 2 | E10: 5.1 Pipeline Capital Costs | F10: 17 | G10: Table 5.1 | H10: 1.1 × 63027 × exp(0.0697D) × L | I10: 2009 USD | J10: material_cost_pipeline | K10: Assumptions and Parameters Pipe – Transmission Pipeline Material | L10: D is nominal pipeline diameter in inches and L is pipeline length in miles. Until pipeline thickness is considered, nominal size equates to inner diameter | M10: https://transitionaccelerator.ca/wp-content/uploads/2023/06/The-Techno-Economics-of-Hydrogen-Pipelines-v2.pdf
A11: TA-PIPE-009 | B11: Primary technical source | C11: The Techno-Economics of Hydrogen Pipelines | D11: 2021 / Version 2 | E11: 5.1 Pipeline Capital Costs | F11: 17 | G11: Table 5.1 | H11: 1.1 × (-51.393D² + 43523D + 16171) × L | I11: 2009 USD | J11: construction_labor_cost_pipeline | K11: Assumptions and Parameters Pipe – Transmission Pipeline Labor | L11: D is nominal pipeline diameter in inches and L is pipeline length in miles.. | M11: https://transitionaccelerator.ca/wp-content/uploads/2023/06/The-Techno-Economics-of-Hydrogen-Pipelines-v2.pdf
A12: TA-PIPE-010 | B12: Primary technical source | C12: The Techno-Economics of Hydrogen Pipelines | D12: 2021 / Version 2 | E12: 5.1 Pipeline Capital Costs | F12: 17 | G12: Table 5.1 | H12: 1.1 × (303.13D² + 12908D + 123245) × L | I12: 2009 USD | J12: miscellaneous_cost_pipeline | K12: Assumptions and Parameters Pipe – Transmission Pipeline Miscellaneous | L12: D is nominal pipeline diameter in inches and L is pipeline length in miles. | M12: https://transitionaccelerator.ca/wp-content/uploads/2023/06/The-Techno-Economics-of-Hydrogen-Pipelines-v2.pdf
A13: TA-PIPE-011 | B13: Primary technical source | C13: The Techno-Economics of Hydrogen Pipelines | D13: 2021 / Version 2 | E13: 5.1 Pipeline Capital Costs | F13: 17 | G13: Table 5.1 | H13: (-9E-13D² + 4417.1D + 164241) × L | I13: 2009 USD | J13: right_of_way_cost_pipeline | K13: Assumptions and Parameters Pipe – Transmission Pipeline Right-of-Way | L13: The source does not apply the 1.1 hydrogen cost multiplier to right-of-way. The quadratic coefficient is effectively zero over the modelled diameter range. | M13: https://transitionaccelerator.ca/wp-content/uploads/2023/06/The-Techno-Economics-of-Hydrogen-Pipelines-v2.pdf
A14: TA-PIPE-012 | B14: Primary technical source | C14: The Techno-Economics of Hydrogen Pipelines | D14: 2021 / Version 2 | E14: 5.1 Pipeline Capital Costs | F14: 18 | G14: Equation 14 | H14: TIC + 0.40 × TIC | I14: 2009 USD | J14: total_capital_investment_pipeline | K14: Transition Accelerator Pipe – Total Capital Investment | L14: TCI equals total installed cost plus indirect capital costs. Equivalent to 1.40 × TIC under the source assumption. | M14: https://transitionaccelerator.ca/wp-content/uploads/2023/06/The-Techno-Economics-of-Hydrogen-Pipelines-v2.pdf
A15: TA-PIPE-013 | B15: Primary technical source | C15: The Techno-Economics of Hydrogen Pipelines | D15: 2021 / Version 2 | E15: 5.2 Pipeline Operating Costs | F15: 18 | G15: Equation 15 | H15: Direct labour + indirect labour + insurance + property tax + licensing and permits + O&M | I15: USD/year or converted CAD/year | J15: total_non_energy_opex_pipeline | K15: Transition Accelerator Pipe – Total non-energy OPEX | L15: Source groups labour and annual TCI-based expenses into non-energy pipeline operating cost. Workbook separates labour as variable and the TCI-based items as fixed for TEMOA mapping. | M15: https://transitionaccelerator.ca/wp-content/uploads/2023/06/The-Techno-Economics-of-Hydrogen-Pipelines-v2.pdf
A16: TA-PIPE-014 | B16: Primary technical source | C16: The Techno-Economics of Hydrogen Pipelines | D16: 2021 / Version 2 | E16: 5.2 Pipeline Operating Costs | F16: 18 | G16: Equation 16 | H16: Annual labour hours × labour rate | I16: currency/year | J16: direct_labor_cost_pipeline | K16: Assumptions and Parameters Pipe – Direct labour costs | L16: Calculated annual direct labour expense. Currency year must remain consistent with the labour-rate input. | M16: https://transitionaccelerator.ca/wp-content/uploads/2023/06/The-Techno-Economics-of-Hydrogen-Pipelines-v2.pdf
A17: TA-PIPE-015 | B17: Primary technical source | C17: The Techno-Economics of Hydrogen Pipelines | D17: 2021 / Version 2 | E17: 5.2 Pipeline Operating Costs | F17: 18 | G17: Equation 17 | H17: 8760 × (x / 100000)^0.25 | I17: hours/year | J17: annual_labor_hours_pipeline | K17: Assumptions and Parameters Pipe – Annual labour hours | L17: x is average pipeline use in kg H2/day with a total 8760 hrs used in the model. 8230 hrs should be considered to represent a proper 40-hour work week annually | M17: https://transitionaccelerator.ca/wp-content/uploads/2023/06/The-Techno-Economics-of-Hydrogen-Pipelines-v2.pdf
A18: TA-PIPE-016 | B18: Primary technical source | C18: The Techno-Economics of Hydrogen Pipelines | D18: 2021 / Version 2 | E18: 5.2 Pipeline Operating Costs | F18: 18 | G18: Equation 18 | H18: 0.5 | I18: fraction of direct labour cost | J18: indirect_labor_factor | K18: Assumptions and Parameters Pipe – Indirect labor factor | L18: Applied to annual direct labour cost to represent overhead, head-office, and personnel expenses. | M18: https://transitionaccelerator.ca/wp-content/uploads/2023/06/The-Techno-Economics-of-Hydrogen-Pipelines-v2.pdf
A19: TA-PIPE-017 | B19: Primary technical source | C19: The Techno-Economics of Hydrogen Pipelines | D19: 2021 / Version 2 | E19: 5.2 Pipeline Operating Costs | F19: 18 | G19: Equation 18 | H19: Direct labour × 0.50 | I19: currency/year | J19: indirect_labor_cost_pipeline | K19: Assumptions and Parameters Pipe – Indirect labour costs | L19: Calculated annual indirect labour cost. | M19: https://transitionaccelerator.ca/wp-content/uploads/2023/06/The-Techno-Economics-of-Hydrogen-Pipelines-v2.pdf
A20: TA-PIPE-018 | B20: Primary technical source | C20: The Techno-Economics of Hydrogen Pipelines | D20: 2021 / Version 2 | E20: 5.2 Pipeline Operating Costs | F20: 18–19 | G20: Equation 19 | H20: 0.01 | I20: fraction of TCI per year | J20: insurance_fraction_pipeline | K20: Assumptions and Parameters Pipe – Insurance | L20: Annual fixed cost equal to 1% of pipeline TCI. | M20: https://transitionaccelerator.ca/wp-content/uploads/2023/06/The-Techno-Economics-of-Hydrogen-Pipelines-v2.pdf
A21: TA-PIPE-019 | B21: Primary technical source | C21: The Techno-Economics of Hydrogen Pipelines | D21: 2021 / Version 2 | E21: 5.2 Pipeline Operating Costs | F21: 18–19 | G21: Equation 19 | H21: 0.01 | I21: fraction of TCI per year | J21: property_tax_fraction_pipeline | K21: Assumptions and Parameters Pipe – Property tax | L21: Annual fixed cost equal to 1% of pipeline TCI. | M21: https://transitionaccelerator.ca/wp-content/uploads/2023/06/The-Techno-Economics-of-Hydrogen-Pipelines-v2.pdf
A22: TA-PIPE-020 | B22: Primary technical source | C22: The Techno-Economics of Hydrogen Pipelines | D22: 2021 / Version 2 | E22: 5.2 Pipeline Operating Costs | F22: 18–19 | G22: Equation 19 | H22: 0.001 | I22: fraction of TCI per year | J22: licensing_permitting_fraction_pipeline | K22: Assumptions and Parameters Pipe – Licensing and permitting | L22: Recurring annual licensing and permitting cost equal to 0.1% of TCI. Distinct from the 3% one-time capital permitting allowance. | M22: https://transitionaccelerator.ca/wp-content/uploads/2023/06/The-Techno-Economics-of-Hydrogen-Pipelines-v2.pdf
A23: TA-PIPE-021 | B23: Primary technical source | C23: The Techno-Economics of Hydrogen Pipelines | D23: 2021 / Version 2 | E23: 5.2 Pipeline Operating Costs | F23: 18–19 | G23: Equation 19 | H23: 0.005 | I23: fraction of TCI per year | J23: operations_maintenance_fraction_pipeline | K23: Assumptions and Parameters Pipe – Operating, maintenance and repairs | L23: Recurring annual O&M cost equal to 0.5% of pipeline TCI. | M23: https://transitionaccelerator.ca/wp-content/uploads/2023/06/The-Techno-Economics-of-Hydrogen-Pipelines-v2.pdf
A24: TA-PIPE-022 | B24: Primary technical source | C24: The Techno-Economics of Hydrogen Pipelines | D24: 2021 / Version 2 | E24: 5.2 Pipeline Operating Costs | F24: 19 | G24: Equation 21 | H24: Insurance + property tax + licensing and permits + O&M | I24: currency/year | J24: total_fixed_opex_pipeline | K24: Transition Accelerator Pipe – Total Fixed OPEX | L24: Workbook maps these non-labour annual costs to CostFixed after normalizing by installed capacity and distance. | M24: https://transitionaccelerator.ca/wp-content/uploads/2023/06/The-Techno-Economics-of-Hydrogen-Pipelines-v2.pdf
A25: TA-PIPE-023 | B25: Primary technical source | C25: The Techno-Economics of Hydrogen Pipelines | D25: 2021 / Version 2 | E25: 5.3 Pipeline Levelized Cost | F25: 20 | G25: Table 5.2 | H25: 0.75 | I25: USD/CAD | J25: exchange_rate_usd_per_cad | K25: Assumptions and Parameters Pipe – Exchange rate | L25: 2019 average exchange rate. Because the ratio is USD per CAD, convert USD to CAD by dividing by 0.75. | M25: https://transitionaccelerator.ca/wp-content/uploads/2023/06/The-Techno-Economics-of-Hydrogen-Pipelines-v2.pdf
A26: TA-PIPE-024 | B26: Primary technical source | C26: The Techno-Economics of Hydrogen Pipelines | D26: 2021 / Version 2 | E26: 5.3 Pipeline Levelized Cost | F26: 20 | G26: Table 5.2 | H26: 49.6 | I26: 2019 CAD/hour | J26: pipeline_labor_rate | K26: Assumptions and Parameters Pipe – Labor Rate | L26: The transition reports this as 2019 $CAD but derived from a 2019 US HDSAM model. Should consider updating this with a Canadian representative value | M26: https://transitionaccelerator.ca/wp-content/uploads/2023/06/The-Techno-Economics-of-Hydrogen-Pipelines-v2.pdf
A27: STATCAN-001 | B27: External conversion source | C27: Gross domestic product implicit price indexes | D27: Statistics Canada data used in workbook | E27: Canada GDP implicit price index | F27: N/A | G27: Table 36-10-0130-01 | H27: 88.5 | I27: index | J27: gdp_deflator_2009 | K27: Assumptions and Parameters Pipe – GDP Deflator 2009 | L27: Used as the source-year price index for escalation of 2009 costs. Confirm that the same series and base-year convention are used for all years. | M27: https://www150.statcan.gc.ca/t1/tbl1/en/tv.action?pid=3610013001
A28: STATCAN-002 | B28: External conversion source | C28: Gross domestic product implicit price indexes | D28: Statistics Canada data used in workbook | E28: Canada GDP implicit price index | F28: N/A | G28: Table 36-10-0130-01 | H28: 103.3 | I28: index | J28: gdp_deflator_2019 | K28: Assumptions and Parameters Pipe – GDP Deflator 2019 | L28: Used for conversion of cost inputs originally expressed in 2019 currency. | M28: https://www150.statcan.gc.ca/t1/tbl1/en/tv.action?pid=3610013001
A29: STATCAN-003 | B29: External conversion source | C29: Gross domestic product implicit price indexes | D29: Statistics Canada data used in workbook | E29: Canada GDP implicit price index | F29: N/A | G29: Table 36-10-0130-01 | H29: 105 | I29: index | J29: gdp_deflator_2020 | K29: Assumptions and Parameters Pipe – GDP Deflator 2020 | L29: Workbook target price-year index. Final normalized cost outputs are currently expressed in real 2020 CAD. | M29: https://www150.statcan.gc.ca/t1/tbl1/en/tv.action?pid=3610013001
A30: NRCAN-001 | B30: External economic source | C30: Energy data and analysis – Canadian electricity prices | D30: 2019 | E30: Alberta electricity price | F30: N/A | G30: Provincial electricity-price data | H30: 0.11 | I30: 2019 CAD/kWh | J30: electricity_price_alberta | K30: Assumptions and Parameters Pipe – Electricity Cost | L30: Used to reproduce monetary compressor electricity OPEX. The preferred CANOE/TEMOA mapping retains electricity as a physical input coefficient rather than embedding this price permanently in CostVariable. | M30: https://natural-resources.canada.ca/science-data/data-analysis/energy-data-analysis
A31: WEI-PIPE-001 | B31: Secondary implementation source | C31: Evaluating Environmental and Economic Trade-offs in Centralized and Decentralized Hydrogen Production — A Case Study on Canadian Steel | D31: 2026 | E31: 2.5.1 Pipeline LCA | F31: 55–56 | G31: Equation 2.10 | H31: (P × D) / (2 × S × F × L × J × T) | I31: mm | J31: t_required | K31: Transition Accelerator Pipe | L31: Minimum required pipeline wall thickness. In the thesis, P and S are in MPa and D is outside diameter in mm. The current workbook does not consider outer diameter into costs. Must validate how this is factored into costs.
A32: WEI-PIPE-002 | B32: Secondary implementation source | C32: Evaluating Environmental and Economic Trade-offs in Centralized and Decentralized Hydrogen Production — A Case Study on Canadian Steel | D32: 2026 | E32: 2.5.1 Pipeline LCA | F32: 55–56 | G32: Equation 2.10 | H32: 483 | I32: MPa | J32: S_yield | K32: Assumptions and Parameters Pipe | L32: Specified minimum yield strength of the selected pipeline steel. The thesis identifies this as an assumption adapted from prior CO2 pipeline literature.
A33: WEI-PIPE-003 | B33: Secondary implementation source | C33: Evaluating Environmental and Economic Trade-offs in Centralized and Decentralized Hydrogen Production — A Case Study on Canadian Steel | D33: 2026 | E33: 2.5.1 Pipeline LCA | F33: 55–56 | G33: Equation 2.10 | H33: 0.72 | I33: dimensionless | J33: F_design | K33: Assumptions and Parameters Pipe | L33: Design factor used in the wall-thickness calculation. The thesis notes that this factor varies with location and pipeline class.
A34: WEI-PIPE-004 | B34: Secondary implementation source | C34: Evaluating Environmental and Economic Trade-offs in Centralized and Decentralized Hydrogen Production — A Case Study on Canadian Steel | D34: 2026 | E34: 2.5.1 Pipeline LCA | F34: 55–56 | G34: Equation 2.10 | H34: 1 | I34: dimensionless | J34: L_location | K34: Assumptions and Parameters Pipe | L34: Locational factor. The thesis holds this at 1.0 and addresses geographic differences separately through routing or cost penalties. Do not confuse this symbol L with physical pipeline length.
A35: WEI-PIPE-005 | B35: Secondary implementation source | C35: Evaluating Environmental and Economic Trade-offs in Centralized and Decentralized Hydrogen Production — A Case Study on Canadian Steel | D35: 2026 | E35: 2.5.1 Pipeline LCA | F35: 55–56 | G35: Equation 2.10 | H35: 1 | I35: dimensionless | J35: J_joint | K35: Assumptions and Parameters Pipe | L35: Joint factor based on seamless pipe.
A36: WEI-PIPE-006 | B36: Secondary implementation source | C36: Evaluating Environmental and Economic Trade-offs in Centralized and Decentralized Hydrogen Production — A Case Study on Canadian Steel | D36: 2026 | E36: 2.5.1 Pipeline LCA | F36: 55–56 | G36: Equation 2.10 | H36: 1 | I36: dimensionless | J36: T_temperature_factor | K36: Assumptions and Parameters Pipe | L36: Temperature derating factor. Set to 1.0 because the pipeline is assumed not to operate above the applicable temperature threshold. This is not a temperature in kelvin despite the current workbook unit label.
A37: TA-PIPE-025 | B37: Primary technical source | C37: The Techno-Economics of Hydrogen Pipelines | D37: 2021 / Version 2 | E37: 4 Gas Pipeline Hydraulics | F37: 10–11 | G37: Equation 1 | H37: 1.1494 × 10^-3 × (Tb/Pb) × [((P1² - exp(s)P2²)/(G × Tf × Le × Z × f))^0.5] × D^2.5 | I37: Sm3/day | J37: Q | K37: Transition Accelerator Pipe | L37: General Flow Equation used to calculate standard volumetric hydrogen flow. D is inside diameter in mm; P1 and P2 must be absolute pressures in kPa. | M37: https://transitionaccelerator.ca/wp-content/uploads/2023/06/The-Techno-Economics-of-Hydrogen-Pipelines-v2.pdf
A38: TA-PIPE-026 | B38: Primary technical source | C38: The Techno-Economics of Hydrogen Pipelines | D38: 2021 / Version 2 | E38: 4 Gas Pipeline Hydraulics | F38: 10–11 | G38: Equation 1 | H38: Variable | I38: mm | J38: D_inner | K38: Transition Accelerator Pipe | L38: Inside pipeline diameter used by the General Flow Equation. This is not automatically equal to nominal pipe size or outside diameter. The current workbook assumes equality for the cost cases and should flag this approximation. | M38: https://transitionaccelerator.ca/wp-content/uploads/2023/06/The-Techno-Economics-of-Hydrogen-Pipelines-v2.pdf
A39: TA-PIPE-027 | B39: Primary technical source | C39: The Techno-Economics of Hydrogen Pipelines | D39: 2021 / Version 2 | E39: 4 Gas Pipeline Hydraulics | F39: 10–11 | G39: Equation 1 variable definition | H39: 288.706 | I39: K | J39: T_b | K39: Assumptions and Parameters Pipe | L39: Base temperature associated with the standard volumetric flow convention. Workbook rounds the value to 288.7 K. | M39: https://transitionaccelerator.ca/wp-content/uploads/2023/06/The-Techno-Economics-of-Hydrogen-Pipelines-v2.pdf
A40: TA-PIPE-028 | B40: Primary technical source | C40: The Techno-Economics of Hydrogen Pipelines | D40: 2021 / Version 2 | E40: 4 Gas Pipeline Hydraulics | F40: 10–11 | G40: Equation 1 variable definition | H40: 101.352 | I40: kPa absolute | J40: P_b | K40: Assumptions and Parameters Pipe | L40: Base pressure associated with the standard volumetric flow convention. The workbook currently uses 101.325 kPa; this small discrepancy should be documented rather than silently treated as identical. | M40: https://transitionaccelerator.ca/wp-content/uploads/2023/06/The-Techno-Economics-of-Hydrogen-Pipelines-v2.pdf
...

Sheet Assumptions and Parameters Pipe
A1: Source Assumptions and Core Equations
A3: Assumptions
A4: Category | B4: Parameter | C4: Value | D4: Unit | E4: Source location | F4: Status/ note
A5: Economic and temporal | B5: Pipeline lifetime | C5: 50 | D5: years | E5: https://transitionaccelerator.ca/wp-content/uploads/2023/06/The-Techno-Economics-of-Hydrogen-Pipelines-v2.pdf | F5: This is a technological physcial lifetime
A6: Economic and temporal | B6: Exchange rate | C6: 0.75 | D6: USD/CAD | E6: https://transitionaccelerator.ca/wp-content/uploads/2023/06/The-Techno-Economics-of-Hydrogen-Pipelines-v2.pdf | F6: Convert USD to CAD by dividing by the USD/CAD exchange rate; 2019 average
A7: Economic and temporal | B7: GDP Deflator 2009 | C7: 88.5 | D7: price index | E7: https://www150.statcan.gc.ca/t1/tbl1/en/tv.action?pid=3610013001&pickMembers%5B0%5D=2.1&cubeTimeFrame.startYear=2009&cubeTimeFrame.endYear=2020&referencePeriods=20090101%2C20200101 | F7: 2017 base year covention
A8: Economic and temporal | B8: GDP Deflator 2019 | C8: 103.3 | D8: price index | E8: https://www150.statcan.gc.ca/t1/tbl1/en/tv.action?pid=3610013001&pickMembers%5B0%5D=2.1&cubeTimeFrame.startYear=2009&cubeTimeFrame.endYear=2020&referencePeriods=20090101%2C20200101 | F8: 2017 base year covention
A9: Economic and temporal | B9: GDP Deflator 2020 | C9: 105 | D9: price index | E9: https://www150.statcan.gc.ca/t1/tbl1/en/tv.action?pid=3610013001&pickMembers%5B0%5D=2.1&cubeTimeFrame.startYear=2009&cubeTimeFrame.endYear=2020&referencePeriods=20090101%2C20200101 | F9: 2017 base year covention
A10: Direct CAPEX assumptions | C10: 1.1 | D10: multiplier | E10: https://transitionaccelerator.ca/wp-content/uploads/2023/06/The-Techno-Economics-of-Hydrogen-Pipelines-v2.pdf | F10: The 1.1 hydrogen pipeline cost multiplier is a weakly supported source assumption and may overlap conceptually with the cost consequences of increased hydrogen-compatible wall thickness. Retain for source reproduction, but test its inclusion in sensitivity analysis. This increased cost burden is effectively addressed via the higher costs and such that are modelled via the thickened pipeline wall needs (thicker than needed for CO2 or nat gas, for e.g.,) though this might not be updated in the version of code shared to you yet. Ill share a final copy once I'm done (since some additional fixes were done as I amended my thesis to its submission state)
A11: Direct CAPEX assumptions | B11: Indirect CAPEX cost assumption multiplier | C11: 0.4 | D11: dimensionless | E11: https://transitionaccelerator.ca/wp-content/uploads/2023/06/The-Techno-Economics-of-Hydrogen-Pipelines-v2.pdf | F11: Source adjustment applied to selected HDSAM transmission-pipeline cost correlations to represent anticipated additional hydrogen-pipeline costs. Retained for source reproduction but flagged for sensitivity analysis
A12: Indirect CAPEX assumptions | B12: Site preparation | C12: 0.05 | D12: fraction of TIC | E12: https://transitionaccelerator.ca/wp-content/uploads/2023/06/The-Techno-Economics-of-Hydrogen-Pipelines-v2.pdf | F12: Includes the purchase of land; grading and excavation of the site; installation and hookup of electrical, water, and sewer systems; and construction of all internal roads, walkways, and parking lots
A13: Indirect CAPEX assumptions | B13: Engineering and Design | C13: 0.1 | D13: fraction of TIC | E13: https://transitionaccelerator.ca/wp-content/uploads/2023/06/The-Techno-Economics-of-Hydrogen-Pipelines-v2.pdf | F13: Includes salaries and overhead for the engineering, drafting, and project management personnel on the project
A14: Indirect CAPEX assumptions | B14: Project Contingency | C14: 0.1 | D14: fraction of TIC | E14: https://transitionaccelerator.ca/wp-content/uploads/2023/06/The-Techno-Economics-of-Hydrogen-Pipelines-v2.pdf | F14: A factor to cover unforeseen circumstances, including project risks or uncertainties). These may include loss of time due to storms and strikes, small changes in the design, and unexpected price increases
A15: Indirect CAPEX assumptions | B15: Permitting | C15: 0.03 | D15: fraction of TIC | E15: https://transitionaccelerator.ca/wp-content/uploads/2023/06/The-Techno-Economics-of-Hydrogen-Pipelines-v2.pdf | F15: The permitting costs are costs borne by the facilities to obtain the necessary approvals to design and install the control equipment. This is a site-specific cost where the costs borne by one facility may not translate well into another facility. However, because of the potential for delay, re-design, and other considerations, permitting costs should be included in the overall cost assessment
A16: Indirect CAPEX assumptions | B16: Unallocated residual | C16: 0.12 | D16: fraction of TIC | E16: https://transitionaccelerator.ca/wp-content/uploads/2023/06/The-Techno-Economics-of-Hydrogen-Pipelines-v2.pdf | F16: Addition 12% associated with the 40% used by the accelerator model.
A17: Labour OPEX assumptions | B17: Labor Rate | C17: 49.6 | D17: $2019 CAD / hr | E17: https://transitionaccelerator.ca/wp-content/uploads/2023/06/The-Techno-Economics-of-Hydrogen-Pipelines-v2.pdf, https://hdsam.es.anl.gov/index.php?content=hdsam | F17: Derived from 2019 US HDSAM model
A18: Labour OPEX assumptions | B18: Indirect labor factor | C18: 0.5 | D18: dimensionless | E18: https://transitionaccelerator.ca/wp-content/uploads/2023/06/The-Techno-Economics-of-Hydrogen-Pipelines-v2.pdf, https://hdsam.es.anl.gov/index.php?content=hdsam | F18: used to consider the cost of overhead (i.e., head office, personnel)
A21: CAPEX, h2_pipe
A22: Category | B22: Parameter | C22: Equation | D22: Unit | E22: Source location | F22: Status / note
A23: CAPEX | B23: Transmission Pipeline Material | C23: 1.1 * 63027*exp(Diameter, in.*0.0697) * (Length, miles) | D23: 2009 $US | E23: https://transitionaccelerator.ca/wp-content/uploads/2023/06/The-Techno-Economics-of-Hydrogen-Pipelines-v2.pdf, https://hdsam.es.anl.gov/index.php?content=hdsam | F23: 2009 $US HDSAM model
A24: CAPEX | B24: Transmission Pipeline Labor | C24: 1.1 * ([-51.393 * (Diameter, in.)2 + 43,523 * (Diameter, in.) + 16,171] * (Length, miles)) | D24: 2009 $US | E24: https://transitionaccelerator.ca/wp-content/uploads/2023/06/The-Techno-Economics-of-Hydrogen-Pipelines-v2.pdf, https://hdsam.es.anl.gov/index.php?content=hdsam | F24: 2009 $US HDSAM model
A25: CAPEX | B25: Transmission Pipeline Miscellaneous | C25: 1.1 * ([303.13 * (Diameter, in.)2 + 12,908 * (Diameter, in.) + 123,245] * (Length, miles)) | D25: 2009 $US | E25: https://transitionaccelerator.ca/wp-content/uploads/2023/06/The-Techno-Economics-of-Hydrogen-Pipelines-v2.pdf, https://hdsam.es.anl.gov/index.php?content=hdsam | F25: 2009 $US HDSAM model
A26: CAPEX | B26: Transmission Pipeline Right-of Way | C26: ([-9E-13 * (Diameter, in.)2 + 4,417.1 * (Diameter, in.) + 164,241] * (Length, miles)) | D26: 2009 $US | E26: https://transitionaccelerator.ca/wp-content/uploads/2023/06/The-Techno-Economics-of-Hydrogen-Pipelines-v2.pdf, https://hdsam.es.anl.gov/index.php?content=hdsam | F26: 2009 $US HDSAM model
A27: Indirect CAPEX | B27: see table above | C27: 40% of TIC | D27: 2009 $US | E27: https://transitionaccelerator.ca/wp-content/uploads/2023/06/The-Techno-Economics-of-Hydrogen-Pipelines-v2.pdf, https://hdsam.es.anl.gov/index.php?content=hdsam | F27: 2009 $US HDSAM model
A30: Capacity-dependent Labour OPEX, h2_pipe
A31: Category | B31: Parameter | C31: Equation | D31: Unit | E31: Source location | F31: Status / note
A32: OPEX, variable | B32: Direct labour costs | C32: Direct labor, pipe ( $ / yr) = Annual hours (hrs / yr ) ∗ Labor rate ( $ / hrs) | D32: $CAD / yr | E32: https://transitionaccelerator.ca/wp-content/uploads/2023/06/The-Techno-Economics-of-Hydrogen-Pipelines-v2.pdf, https://hdsam.es.anl.gov/index.php?content=hdsam | F32: Depends on annual labour hours; 2019 $US
A33: OPEX, variable | B33: Annual labour hours | C33: Annual labor hours (hr / yr) = 8760 ∗ ( x / 100,000) ^ 0.25 | D33: hrs / yr | E33: https://transitionaccelerator.ca/wp-content/uploads/2023/06/The-Techno-Economics-of-Hydrogen-Pipelines-v2.pdf, https://hdsam.es.anl.gov/index.php?content=hdsam
C34: x is avg pipeline use (kg H2 / day)
A35: OPEX, variable | B35: Indirect labour costs | C35: Indirect labor, pipe ( $ / yr) = Direct laborpipe ( $ / yr) ∗ Indirect labor factor (%) | D35: $CAD / yr | F35: 2019 $US
A37: OPEX, Fixed, h2_pipe
A38: Category | B38: Parameter | C38: Equation | D38: Unit | E38: Source location | F38: Status / note
A39: OPEX, fixed | B39: Insurance | C39: 1% of TCI, pipe | D39: fraction of TCI / yr | E39: https://transitionaccelerator.ca/wp-content/uploads/2023/06/The-Techno-Economics-of-Hydrogen-Pipelines-v2.pdf, https://hdsam.es.anl.gov/index.php?content=hdsam | F39: All non-labor fixed O&M costs ($/yr) are calculated as a fraction of the TCI to reflect that the larger and more complex, and therefore more expensive, projects have higher upkeep costs throughout the project life
A40: OPEX, fixed | B40: Property tax | C40: 1% of TCI, pipe | D40: fraction of TCI / yr | E40: https://transitionaccelerator.ca/wp-content/uploads/2023/06/The-Techno-Economics-of-Hydrogen-Pipelines-v2.pdf, https://hdsam.es.anl.gov/index.php?content=hdsam
A41: OPEX, fixed | B41: Licensing and permitting | C41: 0.1% of TCI, pipe | D41: fraction of TCI / yr | E41: https://transitionaccelerator.ca/wp-content/uploads/2023/06/The-Techno-Economics-of-Hydrogen-Pipelines-v2.pdf, https://hdsam.es.anl.gov/index.php?content=hdsam
A42: OPEX, fixed | B42: Operating, maintenance and repairs | C42: 0.5% of TCI, pipe | D42: fraction of TCI / yr | E42: https://transitionaccelerator.ca/wp-content/uploads/2023/06/The-Techno-Economics-of-Hydrogen-Pipelines-v2.pdf, https://hdsam.es.anl.gov/index.php?content=hdsam
A45: Notes about hydrogen cost factor from Ziqi:

Sheet Transition Accelerator Pipe
A1: General Overview | B1: Diameter treatment used in this workbook
A2: This worksheet represents a reference gaseous hydrogen transmission pipeline segment. The current reference length is 250 km. Hydraulic and cost parameters must be revised if the segment length, pressure cycle, pipeline material, or geographic assumptions change. Cost outputs are normalized per kilometre only after the complete segment cost has been calculated | B2: The General Flow Equation uses pipeline inner diameter to determine hydrogen flow capacity. Required wall thickness is calculated from the selected pressure and material-design assumptions, and outside diameter is then calculated as inner diameter plus twice the required wall thickness. The resulting outside diameter is used as the diameter input to the HDSAM-derived pipeline CAPEX correlations. This adaptation introduces the effect of wall thickness into the cost-capacity relationship. It differs from a strict reproduction of the source correlations, which are reported using pipeline diameter without fully distinguishing nominal, inner, and outside diameter. The assumption is therefore documented and should be tested in sensitivity analysis.
A4: Pipeline Thickness Requirements (currently not considered but may influence material costs)
A5: Variable | B5: Description | C5: Default Value | D5: Units | E5: Notes | F5: Source
A6: P | B6: Design Pressure | C6: =C22/1000 -> 7 | D6: Mpa | E6: Unclear if max pressure should be used over average pipeline pressure | F6: Equation 2.9 from https://transitionaccelerator.ca/wp-content/uploads/2023/06/The-Techno-Economics-of-Hydrogen-Pipelines-v2.pdf
A7: S | B7: Specified minimum yield strength | C7: 483 | D7: Mpa | E7: Proxy from a CO2 pipeline TEA by McCoy and Rubin | F7: https://www.sciencedirect.com/science/article/pii/S1750583607001193
A8: F | B8: Design factor | C8: 0.72 | D8: dimensionless | E8: Proxy from a CO2 pipeline TEA by McCoy and Rubin; can vary spatially | F8: https://www.sciencedirect.com/science/article/pii/S1750583607001193
A9: L | B9: Locational factor | C9: 1 | D9: dimensionless | E9: This would be accounted for by a cost surface c(i,j) modifier
A10: J | B10: Joint factor | C10: 1 | D10: dimensionless | E10: Based on seemless welded pipe | F10: https://www.csagroup.org/standards/areas-of-focus/petroleum-natural-gas/standards-for-pipeline-safety/?srsltid=AfmBOoqOn1XJkHisMlvYtqmtJ2wq0C18E_Xcenv9L9HZob5a6nou7gJT
A11: T | B11: Temperature factor | C11: 1 | D11: dimensionless | E11: Pipelines are not operated above 120C thus temperature factor is set to 1 | F11: https://www.csagroup.org/standards/areas-of-focus/petroleum-natural-gas/standards-for-pipeline-safety/?srsltid=AfmBOoqOn1XJkHisMlvYtqmtJ2wq0C18E_Xcenv9L9HZob5a6nou7gJT
A18: Model Units
A19: Variable | B19: Description | C19: Default Value | D19: Units | E19: Status | F19: Notes | G19: Source
A20: Tb | B20: Base temperature | C20: 288.7 | D20: K | E20: Input | F20: Ambient conditions not assuming outdoor temperature varaibility, realistically this would differ in the winter
A21: Pb | B21: Base pressure | C21: 101.325 | D21: kPa | E21: Input | F21: Ambient conditions
A22: P1 | B22: Inlet pressure | C22: 7000 | D22: kPa | E22: Input | F22: Converted from 70 bar | G22: https://transitionaccelerator.ca/wp-content/uploads/2023/06/The-Techno-Economics-of-Hydrogen-Pipelines-v2.pdf, https://hdsam.es.anl.gov/index.php?content=hdsam
A23: P2 | B23: Outlet pressure | C23: 2800 | D23: kPa | E23: Input | F23: Converted from 28 bar | G23: https://transitionaccelerator.ca/wp-content/uploads/2023/06/The-Techno-Economics-of-Hydrogen-Pipelines-v2.pdf, https://hdsam.es.anl.gov/index.php?content=hdsam
A24: H1 | B24: Inlet elevation | C24: 2 | D24: m | E24: Input | F24: Arbitrary assumption to get a baseline reference for a near-flat pipe over 250km
A25: H2 | B25: Outlet elevation | C25: 1 | D25: m | E25: Input
A26: Tf | B26: Average flowing temperature | C26: 288.7 | D26: K | E26: Input | F26: Ambient conditions not assuming outdoor temperature varaibility, realistically this would differ in the winter | G26: Using Tf and https://h2tools.org/hyarc/hydrogen-data/hydrogen-compressibility-different-temperatures-and-pressures
A27: Z | B27: Average gas compressibility factor | C27: 1.03 | D27: dimensionless | E27: Input | F27: Should correspond to P and T conditions of pipe | G27: https://www.engineeringtoolbox.com/specific-gravities-gases-d_334.html
A28: G | B28: H2 gas specific gravity relative to air | C28: 0.0696 | D28: dimensionless | E28: Input | F28: Used by the general flow equation | G28: https://www.sciencedirect.com/science/article/pii/S095965261832170X?via%3Dihub
A29: L | B29: Pipeline segment length | C29: 250 | D29: km | E29: Input | F29: Reference engineering case, should be checked for sensitivity | G29: Assumed from https://transitionaccelerator.ca/wp-content/uploads/2023/06/The-Techno-Economics-of-Hydrogen-Pipelines-v2.pdf
A30: f | B30: Darcy fricton factor | C30: 0.0094 | D30: dimensionless | E30: Input | F30: Dervied from Reynolds numbers and iterative solving; need to be re-solved if parameters are changed | G30: https://transitionaccelerator.ca/wp-content/uploads/2023/06/The-Techno-Economics-of-Hydrogen-Pipelines-v2.pdf, https://hdsam.es.anl.gov/index.php?content=hdsam
A31: R | B31: Universal Gas Constant | C31: 8.314 | D31: kPa*m^3/k*mol | E31: Input constant | G31: https://transitionaccelerator.ca/wp-content/uploads/2023/06/The-Techno-Economics-of-Hydrogen-Pipelines-v2.pdf, https://hdsam.es.anl.gov/index.php?content=hdsam
A32: rho H2,b | B32: Hydrogen density at base conditions | C32: 0.0834 | D32: kg H2/Sm^3 | E32: Conversion factor | F32: Used to convert Q to mass capacity | G32: https://transitionaccelerator.ca/wp-content/uploads/2023/06/The-Techno-Economics-of-Hydrogen-Pipelines-v2.pdf, https://hdsam.es.anl.gov/index.php?content=hdsam
A33: nd | B33: days per representative year | C33: 365 | D33: days/year | E33: CANOE conversion | F33: Converts daily capacity into annual capcity
A36: Derived Hydraulic Parameters
A37: Variable | B37: Description | C37: Default Value | D37: Units | E37: Status | F37: Notes | G37: Source
A38: s | B38: Elevation adjustment parameter | C38: =0.0684*C28*((C25-C24)/(C26*C27)) -> -1.6009631e-05 | D38: dimensionless | E38: Derived input | F38: Derived from elevation, G, Tf, and Z | G38: Equation 2.7 from https://transitionaccelerator.ca/wp-content/uploads/2023/06/The-Techno-Economics-of-Hydrogen-Pipelines-v2.pdf
A39: Le | B39: Equivalent pipeline length | C39: =C29*((EXP(C38)-1)/C38) -> 249.998 | D39: km | E39: Derived input | F39: Derived from L and s | G39: https://transitionaccelerator.ca/wp-content/uploads/2023/06/The-Techno-Economics-of-Hydrogen-Pipelines-v2.pdf, https://hdsam.es.anl.gov/index.php?content=hdsam
A40: Pavg | B40: Average pipeline pressure | C40: =(2/3)*(((C22^3)-(C23^3))/((C22^2)-(C23^2))) -> 5200 | D40: kPa | E40: Derived input | F40: Dervied from P1 and P2 | G40: Equation 2.9 from https://transitionaccelerator.ca/wp-content/uploads/2023/06/The-Techno-Economics-of-Hydrogen-Pipelines-v2.pdf
A41: Vmax | B41: Erosional Velocity | C41: =100*SQRT((0.05131*((C27*C31*C26)/(C28*C22)))) -> 51.026336 | D41: m/s | E41: Derived input | F41: Equation 8 in transition accelerator | G41: https://transitionaccelerator.ca/wp-content/uploads/2023/06/The-Techno-Economics-of-Hydrogen-Pipelines-v2.pdf, https://hdsam.es.anl.gov/index.php?content=hdsam
A42: Cday | B42: Daily mass capacity | C42: Output | D42: kg H2/day | E42: Derived input
A43: Cyr | B43: Annual mass capacity | C43: Output | D43: t H2/yr | E43: Derived input
A46: Transmission Pipeline Capacity Estimation
A47: Design_ID | B47: Inner pipeline Diameter (inch, inner diameter) | C47: Inner pipeline diameter (mm) | D47: Required pipeline thickness (mm) | E47: Outer Pipeline Diameter (mm) | F47: Gas flow rate (Sm^3/day) | G47: Daily Capacity (kg H2 / day) | H47: Annual Capacity (kg H2 / year) | I47: Annual Capacity (t H2 / year)
A48: H2_PIPE_8 | B48: 8 | C48: =B48*25.4 -> 203.2 | D48: =($C$6*(B48*25.4))/(2*$C$7*$C$8*$C$9*$C$10*$C$11) -> 2.0450886 | E48: =D48+C48 -> 205.24509 | F48: =1.1494*(10^(-3))*($C$20/$C$21)*(((($C$22^2)-EXP($C$38)*($C$23^2))/($C$28*$C$26*$C$39*$C$27*$C$30))^0.5)*(C48^2.5) -> 1773250.7 | G48: =F48*0.0834 -> 147889.11 | H48: =G48*$C$33 -> 53979526 | I48: =H48/1000 -> 53979.526
A49: H2_PIPE_10 | B49: 10 | C49: =B49*25.4 -> 254 | D49: =($C$6*(B49*25.4))/(2*$C$7*$C$8*$C$9*$C$10*$C$11) -> 2.5563607 | E49: =D49+C49 -> 256.55636 | F49: =1.1494*(10^(-3))*($C$20/$C$21)*(((($C$22^2)-EXP($C$38)*($C$23^2))/($C$28*$C$26*$C$39*$C$27*$C$30))^0.5)*(C49^2.5) -> 3097741.6 | G49: =F49*0.0834 -> 258351.65 | H49: =G49*$C$33 -> 94298351 | I49: =H49/1000 -> 94298.351
A50: H2_PIPE_12 | B50: 12 | C50: =B50*25.4 -> 304.8 | D50: =($C$6*(B50*25.4))/(2*$C$7*$C$8*$C$9*$C$10*$C$11) -> 3.0676329 | E50: =D50+C50 -> 307.86763 | F50: =1.1494*(10^(-3))*($C$20/$C$21)*(((($C$22^2)-EXP($C$38)*($C$23^2))/($C$28*$C$26*$C$39*$C$27*$C$30))^0.5)*(C50^2.5) -> 4886504.5 | G50: =F50*0.0834 -> 407534.47 | H50: =G50*$C$33 -> 1.4875008e+08 | I50: =H50/1000 -> 148750.08
A51: H2_PIPE_14 | B51: 14 | C51: =B51*25.4 -> 355.6 | D51: =($C$6*(B51*25.4))/(2*$C$7*$C$8*$C$9*$C$10*$C$11) -> 3.578905 | E51: =D51+C51 -> 359.1789 | F51: =1.1494*(10^(-3))*($C$20/$C$21)*(((($C$22^2)-EXP($C$38)*($C$23^2))/($C$28*$C$26*$C$39*$C$27*$C$30))^0.5)*(C51^2.5) -> 7183982.6 | G51: =F51*0.0834 -> 599144.15 | H51: =G51*$C$33 -> 2.1868762e+08 | I51: =H51/1000 -> 218687.62
...

Sheet Assumptions and Parameter Comp
A1: Source Assumptions and Core Equations
A3: Thermodynamic Compressor Assumptions
A4: Category | B4: Parameter | C4: Value | D4: Unit | E4: Source location | F4: Status/ note
A5: Gas property | B5: Hydrogen molar mass | C5: 0.002016 | D5: kg/mol | E5: Transition Accelerator compression brief | F5: Used to convert hydrogen mass flow to molar flow.
A6: Gas property | B6: Heat-capacity ratio | C6: 1.405 | D6: dimensionless | E6: Transition Accelerator compression brief | F6: Ratio of Cp to Cv for hydrogen under the assumed operating conditions.
A7: Gas property | B7: Compressibility factor | C7: 1.03 | D7: dimensionless | E7: Wei thesis / workbook methodology | F7: Average value over the selected 28-to-70 bar compression range. Reassess if pressure or temperature assumptions change.
A8: Thermodynamic | B8: Universal gas constant | C8: 8.314 | D8: J/(mol·K) | E8: Transition Accelerator compression brief | F8: Unit basis must remain consistent with molar flow and temperature in the compressor power equation.
A9: Thermodynamic | B9: Suction temperature | C9: 289 | D9: K | E9: Wei thesis | F9: Compressor inlet temperature. Complete intercooling returns hydrogen to this temperature after each stage.
A10: Pressure | B10: Suction pressure | C10: 28 | D10: bar absolute | E10: Wei thesis / workbook methodology | F10: Matches the outlet pressure of the associated pipeline segment.
A11: Pressure | B11: Discharge pressure | C11: 70 | D11: bar absolute | E11: Transition Accelerator pipeline design / Wei thesis | F11: Matches the inlet pressure of the following pipeline segment.
A12: Staging | B12: Maximum pressure ratio per stage | C12: 2.1 | D12: ratio | E12: Transition Accelerator compression brief | F12: Used to calculate the minimum number of compression stages.
A13: Staging | B13: Equal pressure ratio across stages | C13: TRUE | D13: Boolean | E13: Transition Accelerator compression brief | F13: Assumes each stage applies the same pressure ratio.
A14: Staging | B14: Complete intercooling | C14: TRUE | D14: Boolean | E14: Transition Accelerator compression brief | F14: Hydrogen is cooled to the initial suction temperature after each stage.
A15: Staging | B15: Intercooler pressure drop | C15: 0 | D15: fraction | E15: Transition Accelerator compression brief | F15: Idealized assumption; no pressure loss between stages.
A16: Efficiency | B16: Electric motor efficiency | C16: 0.95 | D16: fraction | E16: Transition Accelerator compression brief | F16: Converts compressor shaft power to electrical input power.
A17: Efficiency | B17: Reference isentropic efficiency | C17: 0.8 | D17: fraction | E17: Transition Accelerator compression brief | F17: Source reference value for large pipeline compressors.
A18: Efficiency | B18: Maximum isentropic efficiency | C18: 0.88 | D18: fraction | E18: Wei thesis | F18: Upper bound used in the capacity-dependent efficiency relationship.
A19: Equipment sizing | B19: Maximum rated power per compressor unit | C19: 16000 | D19: kW/unit | E19: Transition Accelerator compression brief | F19: Required station power above this value must be divided among multiple compressor units.
A20: Equipment sizing | B20: Number of operating compressor units | C20: Ceiling(P_station / 16000) | D20: units | E20: Derived workbook equation | F20: Parallel units are sized so that no individual unit exceeds 16 MW.
A21: Equipment sizing | B21: Rated power per compressor unit | C21: P_station / n_units | D21: kW/unit | E21: Derived workbook equation | F21: Equal sizing across operating units unless an alternative configuration is introduced.
A22: Equipment sizing | B22: Standby compressor units | C22: 0 | D22: units | E22: Workbook methodology | F22: No N+1 redundancy included in the base case. Add only as a separate reliability assumption.
A23: Segment configuration | B23: Reference pipeline segment length | C23: 250 | D23: km | E23: Wei thesis | F23: One recompression station is associated with each 250 km pipeline segment.
A24: Segment configuration | B24: Compressor stations per segment | C24: 1 | D24: station/segment | E24: Workbook methodology | F24: Used to normalize station CAPEX, fixed OPEX, and electricity intensity by distance.
A25: Temporal | B25: Days per year | C25: 365 | D25: days/year | E25: Workbook convention | F25: Used to convert daily hydrogen capacity to annual capacity.
A26: Temporal | B26: Hours per day | C26: 24 | D26: hours/day | E26: Workbook convention | F26: Used to calculate daily compressor electricity consumption.
A27: Temporal | B27: Hours per year | C27: 8760 | D27: hours/year | E27: Workbook convention | F27: Used only where annual full-load operation is explicitly required.
A30: Compressor Cost Assumptions
A31: Category | B31: Parameter | C31: Value | D31: Unit | E31: Source location | F31: Status/ note
A32: CAPEX | B32: Uninstalled cost coefficient | C32: 3083.3 | D32: 2019 CAD coefficient | E32: https://transitionaccelerator.ca/wp-content/uploads/2023/04/TA-Technical-Brief-1.1_TEEA-Hydrogen-Compression_PUBLISHED.pdf | F32: Applied as UC = 3083.3 × P_unit^0.8335, where rated motor power is in kW. Published coefficient already incorporates source escalation and USD-to-CAD conversion.
A33: CAPEX | B33: Scale exponent | C33: 0.8335 | D33: dimensionless | E33: https://transitionaccelerator.ca/wp-content/uploads/2023/04/TA-Technical-Brief-1.1_TEEA-Hydrogen-Compression_PUBLISHED.pdf | F33: Economies-of-scale exponent for the large pipeline-compressor correlation.
A34: CAPEX | B34: Installation factor | C34: 2 | D34: multiplier | E34: https://transitionaccelerator.ca/wp-content/uploads/2023/04/TA-Technical-Brief-1.1_TEEA-Hydrogen-Compression_PUBLISHED.pdf | F34: Converts uninstalled compressor cost to total installed cost: TIC = UC × IF.
A35: CAPEX | B35: Compressor unit lifetime | C35: 15 | D35: years | E35: https://transitionaccelerator.ca/wp-content/uploads/2023/04/TA-Technical-Brief-1.1_TEEA-Hydrogen-Compression_PUBLISHED.pdf | F35: Use as physical technology lifetime for TEMOA. Do not embed a CRF in CostInvest.
A36: CAPEX | B36: Published source currency year | C36: 2019 | D36: year | E36: https://transitionaccelerator.ca/wp-content/uploads/2023/04/TA-Technical-Brief-1.1_TEEA-Hydrogen-Compression_PUBLISHED.pdf | F36: Published compressor cost correlation is reported in 2019 CAD.
A37: CAPEX | B37: Target workbook currency year | C37: 2020 | D37: year | E37: Workbook methodology | F37: All compressor CAPEX and OPEX outputs are converted to real 2020 CAD before normalization.
A38: Indirect CAPEX | B38: Site preparation fraction | C38: 0.05 | D38: fraction of TIC | E38: Wei thesis, Section 2.5.4.2 | F38: Added to compressor TIC when reproducing the Wei implementation.
A39: Indirect CAPEX | B39: Engineering and design fraction | C39: 0.1 | D39: fraction of TIC | E39: Wei thesis, Section 2.5.4.2 | F39: Added to compressor TIC when reproducing the Wei implementation.
A40: Indirect CAPEX | B40: Project contingency fraction | C40: 0.1 | D40: fraction of TIC | E40: Wei thesis, Section 2.5.4.2 | F40: Added to compressor TIC when reproducing the Wei implementation.
A41: Indirect CAPEX | B41: Permitting fraction | C41: 0.03 | D41: fraction of TIC | E41: Wei thesis, Section 2.5.4.2 | F41: One-time capital permitting cost. Distinct from annual licensing and permitting OPEX.
A42: Indirect CAPEX | B42: Total indirect CAPEX fraction | C42: 0.28 | D42: fraction of TIC | E42: Wei thesis, Section 2.5.4.2 | F42: Sum of site preparation, engineering and design, contingency, and permitting.
A43: Indirect CAPEX | B43: Total capital investment | C43: TIC × 1.28 | D43: 2019 CAD | E43: Wei thesis, Equation 2.19 and Section 2.5.4.2 | F43: TCI = TIC plus 28% indirect capital costs under the thesis implementation.
...

Sheet Transition Accelerator Compress
A1: General Overview
A2: Reconstructs the hydrogen compressor thermodynamic, equipment-sizing, capital-cost, operating-cost, and electricity-consumption calculations for each pipeline capacity case. It links compressor flow cases to the corresponding pipeline design cases, divides required station power among physically allowable compressor units, converts source-year costs to the workbook currency basis, and normalizes compressor CAPEX, fixed OPEX, labour OPEX, and electricity requirements by capacity and reference segment length for combination with the pipeline subsystem.
A5: Notes: | B5: Multistage compressor assumptions:
A6: This is a representative model for a compressor associated with 250km long H2 pipeline segments | B6: i. the work is equal at each stage
A7: Parameters must be adjusted if another distance is chosen (see previous worksheet) | B7: ii. Pressure ratio per stage is equal
A8: Units have been normalized per km to ensure edge distance can be multiplied | B8: iii. Temperature of gas in intercoolers is cooled to original suction temperature of first stage
A9: Current model Assumed Nominal pipeline size = inner diameter | B9: iv. There is no pressure drop or heat losses that occur in intercoolers between stages
A10: Currently, an isentropic multistage reciprocating piston compressor is considered as the reference | B10: v. Isentropic efficiency factor (n,isen) was capped at 0.88 as a performance cap given that curren literature values suggest 0.80 as the current hard cap.
A11: The model uses indirect capital costs of 40% of total investment costs but only 28% were categorized in the accelerator document. This should be treated using sensitvity
A14: Cost Assumptions
A15: Factor | B15: Default Value | C15: Units | D15: Notes | E15: Source
A16: Exchange rate | B16: 0.75 | C16: USD/CAD | D16: 2019 average exchange rate used by the source to convert the underlying compressor cost correlation from USD to CAD. Already embedded in the published 3083.3 coefficient; do not apply again. | E16: The Techno-Economics of Hydrogen Compression, Table 4.2
A17: CEPCI escalation factor | B17: 1.179 | C17: multiplier | D17: Calculated as 619.2 / 525.4 to escalate the underlying 2007 equipment-cost correlation to 2019. Already embedded in the published 3083.3 coefficient; retain only for provenance. | E17: The Techno-Economics of Hydrogen Compression, Table 4.2
A18: Discount rate | B18: 0.08 | C18: fraction | D18: Source weighted-average cost of capital used to calculate the capital recovery factor and reproduce levelized compressor costs. Do not embed this annualization in TEMOA CostInvest. | E18: The Techno-Economics of Hydrogen Compression, Table 4.2
A19: Project lifetime | B19: 15 | C19: years | D19: Source compressor economic lifetime used in the capital recovery factor. Use as the compressor technology lifetime in TEMOA unless a different physical lifetime is selected. | E19: The Techno-Economics of Hydrogen Compression, Table 4.2
A20: Source availability factor | B20: 0.9 | C20: fraction | D20: Source assumption used to calculate annual hydrogen throughput and levelized compressor costs. Represents approximately 10% downtime for maintenance and unplanned outages. | E20: The Techno-Economics of Hydrogen Compression, Section 4.2 and Table 4.2
A21: Workbook design-capacity factor | B21: 1 | C21: fraction | D21: Workbook convention used when annual design capacity is calculated as daily capacity × 365. This is not the source availability assumption and should not constrain endogenous TEMOA activity. | E21: Workbook methodology
A22: Scale exponent | B22: 0.8335 | C22: dimensionless | D22: Exponent in the pipeline-compressor uninstalled-cost relationship: UC = 3083.3 × P^0.8335. Power must be entered in kW. | E22: The Techno-Economics of Hydrogen Compression, Table 4.1
A23: Installation factor | B23: 2 | C23: multiplier | D23: Converts uninstalled compressor equipment cost to total installed cost: TIC = UC × 2. | E23: The Techno-Economics of Hydrogen Compression, Table 4.1
A24: Annual calendar hours | B24: =24*365 -> 8760 | C24: hours/year | D24: Used only for annual full-load electricity calculations. Physical electricity intensity should normally be calculated directly from rated power and hydrogen throughput. | E24: Workbook convention
A25: Electricity price | B25: 0.11 | C25: 2019 CAD/kWh_e | D25: Alberta industrial electricity price used to reproduce source compressor energy OPEX. Prefer mapping compressor electricity as a physical input coefficient in TEMOA rather than embedding this price in CostVariable. | E25: The Techno-Economics of Hydrogen Compression, Table 4.2
A26: Target workbook currency year | B26: 2020 | C26: year | D26: Final compressor CAPEX and non-energy OPEX are converted from 2019 CAD to real 2020 CAD using the selected workbook escalation convention. | E26: Workbook methodology
A27: GDP deflator 2019 | B27: 103.3 | C27: price index | D27: Source-year index for converting 2019 CAD compressor costs to the workbook target price year. Uses the selected Statistics Canada GDP implicit price-index series. | E27: Statistics Canada Table 36-10-0130-01
A28: GDP deflator 2020 | B28: 105 | C28: price index | D28: Target-year index for expressing compressor costs in real 2020 CAD. | E28: Statistics Canada Table 36-10-0130-01
A31: Model Input Paramters
A32: Variable | B32: Description | C32: Default Value | D32: Unit | E32: Status | F32: Notes | G32: Source
A33: M_H2 | B33: Hydrogen molar mass | C33: 0.002 | D33: kg/mol | E33: Input | F33: Use 0.002016 kg/mol rather than 0.002 kg/mol unless reproducing a rounded source calculation. This converts hydrogen mass flow to molar flow. | G33: Transition Accelerator compression brief; standard physical constant
A34: k | B34: Ratio of hydrogen specific heat at constant pressure to specific heat at constant volume, Cp/Cv | C34: 1.405 | D34: dimensionless | E34: Input | F34: Assumed constant over the selected compressor operating range. The Transition Accelerator brief commonly rounds this value to 1.41; retain 1.405 if used consistently in all calculations. | G34: Transition Accelerator compression brief
A35: Z | B35: Average hydrogen compressibility factor | C35: 1.03 | D35: dimensionless | E35: Input | F35: Average value used over the assumed pressure and temperature range. Recalculate or test sensitivity if suction pressure, discharge pressure, or temperature changes materially. | G35: Wei thesis, Section 2.5.2; pipeline-model assumption
A36: r_stage,max | B36: Maximum allowable compression ratio per stage | C36: 2.1 | D36: dimensionless | E36: Input | F36: Used to determine the minimum number of compressor stages. The compression brief notes that feasible ratios vary by compressor type; 2.1 is the selected pipeline-compressor assumption, not a universal limit. | G36: Transition Accelerator compression brief
A37: T_suction | B37: Compressor suction temperature | C37: 289 | D37: K | E37: Input | F37: Assumed approximately equal to ambient temperature. Under complete intercooling, hydrogen is returned to this temperature between stages. | G37: Wei thesis; workbook assumption
